Workbook

Sheet Lisez-moi
A1: Opération Château v2 — Prévisionnels 10 ans
A2: Généré le 2026-10-14 par build_model.py à partir de hypotheses.py. Toutes les cellules de calcul sont des formules : modifiez les cellules jaunes (texte bleu) pour recalculer.
A3: Statuts des hypothèses (colonne D des blocs, colonne G des tableaux) : PL = page lue, EX = extrait de recherche, EST = estimation, INC = inconnu. Aucun financement, investisseur, vendeur ou subvention n'est acquis.
A4: Bien de référence : château + ~40-50 ha + écuries existantes à 2,5 M€ = médiane de 19 annonces de châteaux ≥ 30 ha (agent 1, pages lues). Exemple réel le plus proche : Ygrande (03), 2,65 M€, 40,7 ha, 24 boxes, manège, 16 chambres (vente SAFER, page lue).
A5: Scénario A — Château équestre « sport » : pension travail avec cavalier professionnel, valorisation et vente de jeunes chevaux, concours, pension premium. Financement bancaire classique (apport 1 M€).
A6: Scénario B — Château multiactivité : pension premium + pré + retraite, mariages plafonnés, gîte, séminaires, tournages. Financement bancaire classique (apport 1 M€).
A7: Variantes de financement de B : B_club_deal (apport 250 k€ + investisseurs majoritaires), B_credit_vendeur (apport 250 k€ + crédit-vendeur 1,5 M€), B_sans_dette (diagnostic de l'exploitation seule).
A8: Scénario C — Le capital d'abord : holding de reprise de PME 2026-2030, achat en année 5 (2031) presque sans dette, exploitation frugale. Les fonds propres viennent de la holding (NON acquis). C_holding_realiste : la holding n'apporte que ce qu'une reprise unique dégage. Feuilles H1-H3 : moteur de capital (ce que 1 à 3 reprises de PME produisent réellement).
A9: Scénario E — Bail emphytéotique : contrôle d'un domaine public pendant 50-99 ans sans propriété ; travaux à la charge du preneur ; redevance INCONNUE ; aucune valeur de sortie (améliorations au bailleur).
A10: Cas prudent / optimiste : dérivés du central (volumes, prix, charges, travaux, montée en charge) — voir Sources_hypotheses. Stress tests (feuilles S_*) : appliqués aux configurations non déficitaires.
A11: Simplifications : IS 25 % sans taux réduit ni plafonnement des déficits ; montants HT ; amortissements bâti 30 ans / travaux 15 ans ; pas de dividendes avant la sortie ; valeur de sortie = % du coût historique moins frais de cession ; loyer privé du fondateur hors CA d'exploitation.
A12: Verdict : VIABLE si trésorerie jamais négative, trésorerie an 10 ≥ réserve, DSCR (après gros entretien) ≥ 1,2 et cash-flow libre ≥ 0 dès la 2e année d'exploitation, TRI des investisseurs extérieurs ≥ 6 % et dirigeant payé par le domaine. NON AUTOFINANCÉ si tout passe sauf la rémunération du dirigeant. Sinon FRAGILE ou NON VIABLE.
A13: Corrections après audit (agent 8) : loyer privé retiré ; prix de pension ramenés au 3e quartile hors IdF (box 450 € TTC) ; 3 ETP pour ~54 équidés ; assurance 12 k€ ; gros entretien sur bâti + travaux ; IS 15 %/25 % ; crédit-vendeur aux conditions de marché ; prêts d'honneur comptés en dette ; C négocié limité à −20 % sur le prix ; valeur de sortie hors gros entretien ; indexation des charges = prix.

Sheet Comparaison
A1: Comparaison des scénarios et stress tests (valeurs liées aux feuilles)
A3: Feuille | B3: Emplois totaux | C3: Ressources prévues | D3: CA an 5 | E3: EBITDA an 5 | F3: EBITDA an 10 | G3: Part équestre CA an 5 | H3: Trésorerie min. | I3: Trésorerie an 10 | J3: DSCR min. (exploitation an 2+) | K3: Années FCF < 0 (exploitation an 2+) | L3: Dette soutenable | M3: Fonds propres nécessaires | N3: TRI investisseurs | O3: TRI fondateur | P3: Capital fondateur | Q3: Votes fondateur | R3: Verdict
A4: A_central | B4: ='A_central'!$B$184 | C4: ='A_central'!$B$185 | D4: ='A_central'!$B$186 | E4: ='A_central'!$B$187 | F4: ='A_central'!$B$188 | G4: ='A_central'!$B$189 | H4: ='A_central'!$B$190 | I4: ='A_central'!$B$191 | J4: ='A_central'!$B$192 | K4: ='A_central'!$B$193 | L4: ='A_central'!$B$196 | M4: ='A_central'!$B$197 | N4: ='A_central'!$B$194 | O4: ='A_central'!$B$195 | P4: ='A_central'!$B$198 | Q4: ='A_central'!$B$199 | R4: ='A_central'!$B$200
A5: A_prudent | B5: ='A_prudent'!$B$184 | C5: ='A_prudent'!$B$185 | D5: ='A_prudent'!$B$186 | E5: ='A_prudent'!$B$187 | F5: ='A_prudent'!$B$188 | G5: ='A_prudent'!$B$189 | H5: ='A_prudent'!$B$190 | I5: ='A_prudent'!$B$191 | J5: ='A_prudent'!$B$192 | K5: ='A_prudent'!$B$193 | L5: ='A_prudent'!$B$196 | M5: ='A_prudent'!$B$197 | N5: ='A_prudent'!$B$194 | O5: ='A_prudent'!$B$195 | P5: ='A_prudent'!$B$198 | Q5: ='A_prudent'!$B$199 | R5: ='A_prudent'!$B$200
A6: A_optimiste | B6: ='A_optimiste'!$B$184 | C6: ='A_optimiste'!$B$185 | D6: ='A_optimiste'!$B$186 | E6: ='A_optimiste'!$B$187 | F6: ='A_optimiste'!$B$188 | G6: ='A_optimiste'!$B$189 | H6: ='A_optimiste'!$B$190 | I6: ='A_optimiste'!$B$191 | J6: ='A_optimiste'!$B$192 | K6: ='A_optimiste'!$B$193 | L6: ='A_optimiste'!$B$196 | M6: ='A_optimiste'!$B$197 | N6: ='A_optimiste'!$B$194 | O6: ='A_optimiste'!$B$195 | P6: ='A_optimiste'!$B$198 | Q6: ='A_optimiste'!$B$199 | R6: ='A_optimiste'!$B$200
A7: B_central | B7: ='B_central'!$B$180 | C7: ='B_central'!$B$181 | D7: ='B_central'!$B$182 | E7: ='B_central'!$B$183 | F7: ='B_central'!$B$184 | G7: ='B_central'!$B$185 | H7: ='B_central'!$B$186 | I7: ='B_central'!$B$187 | J7: ='B_central'!$B$188 | K7: ='B_central'!$B$189 | L7: ='B_central'!$B$192 | M7: ='B_central'!$B$193 | N7: ='B_central'!$B$190 | O7: ='B_central'!$B$191 | P7: ='B_central'!$B$194 | Q7: ='B_central'!$B$195 | R7: ='B_central'!$B$196
A8: B_prudent | B8: ='B_prudent'!$B$180 | C8: ='B_prudent'!$B$181 | D8: ='B_prudent'!$B$182 | E8: ='B_prudent'!$B$183 | F8: ='B_prudent'!$B$184 | G8: ='B_prudent'!$B$185 | H8: ='B_prudent'!$B$186 | I8: ='B_prudent'!$B$187 | J8: ='B_prudent'!$B$188 | K8: ='B_prudent'!$B$189 | L8: ='B_prudent'!$B$192 | M8: ='B_prudent'!$B$193 | N8: ='B_prudent'!$B$190 | O8: ='B_prudent'!$B$191 | P8: ='B_prudent'!$B$194 | Q8: ='B_prudent'!$B$195 | R8: ='B_prudent'!$B$196
A9: B_optimiste | B9: ='B_optimiste'!$B$180 | C9: ='B_optimiste'!$B$181 | D9: ='B_optimiste'!$B$182 | E9: ='B_optimiste'!$B$183 | F9: ='B_optimiste'!$B$184 | G9: ='B_optimiste'!$B$185 | H9: ='B_optimiste'!$B$186 | I9: ='B_optimiste'!$B$187 | J9: ='B_optimiste'!$B$188 | K9: ='B_optimiste'!$B$189 | L9: ='B_optimiste'!$B$192 | M9: ='B_optimiste'!$B$193 | N9: ='B_optimiste'!$B$190 | O9: ='B_optimiste'!$B$191 | P9: ='B_optimiste'!$B$194 | Q9: ='B_optimiste'!$B$195 | R9: ='B_optimiste'!$B$196
A10: B_club_deal | B10: ='B_club_deal'!$B$180 | C10: ='B_club_deal'!$B$181 | D10: ='B_club_deal'!$B$182 | E10: ='B_club_deal'!$B$183 | F10: ='B_club_deal'!$B$184 | G10: ='B_club_deal'!$B$185 | H10: ='B_club_deal'!$B$186 | I10: ='B_club_deal'!$B$187 | J10: ='B_club_deal'!$B$188 | K10: ='B_club_deal'!$B$189 | L10: ='B_club_deal'!$B$192 | M10: ='B_club_deal'!$B$193 | N10: ='B_club_deal'!$B$190 | O10: ='B_club_deal'!$B$191 | P10: ='B_club_deal'!$B$194 | Q10: ='B_club_deal'!$B$195 | R10: ='B_club_deal'!$B$196
A11: B_credit_vendeur | B11: ='B_credit_vendeur'!$B$180 | C11: ='B_credit_vendeur'!$B$181 | D11: ='B_credit_vendeur'!$B$182 | E11: ='B_credit_vendeur'!$B$183 | F11: ='B_credit_vendeur'!$B$184 | G11: ='B_credit_vendeur'!$B$185 | H11: ='B_credit_vendeur'!$B$186 | I11: ='B_credit_vendeur'!$B$187 | J11: ='B_credit_vendeur'!$B$188 | K11: ='B_credit_vendeur'!$B$189 | L11: ='B_credit_vendeur'!$B$192 | M11: ='B_credit_vendeur'!$B$193 | N11: ='B_credit_vendeur'!$B$190 | O11: ='B_credit_vendeur'!$B$191 | P11: ='B_credit_vendeur'!$B$194 | Q11: ='B_credit_vendeur'!$B$195 | R11: ='B_credit_vendeur'!$B$196
A12: B_sans_dette | B12: ='B_sans_dette'!$B$180 | C12: ='B_sans_dette'!$B$181 | D12: ='B_sans_dette'!$B$182 | E12: ='B_sans_dette'!$B$183 | F12: ='B_sans_dette'!$B$184 | G12: ='B_sans_dette'!$B$185 | H12: ='B_sans_dette'!$B$186 | I12: ='B_sans_dette'!$B$187 | J12: ='B_sans_dette'!$B$188 | K12: ='B_sans_dette'!$B$189 | L12: ='B_sans_dette'!$B$192 | M12: ='B_sans_dette'!$B$193 | N12: ='B_sans_dette'!$B$190 | O12: ='B_sans_dette'!$B$191 | P12: ='B_sans_dette'!$B$194 | Q12: ='B_sans_dette'!$B$195 | R12: ='B_sans_dette'!$B$196
A13: B_frugal | B13: ='B_frugal'!$B$178 | C13: ='B_frugal'!$B$179 | D13: ='B_frugal'!$B$180 | E13: ='B_frugal'!$B$181 | F13: ='B_frugal'!$B$182 | G13: ='B_frugal'!$B$183 | H13: ='B_frugal'!$B$184 | I13: ='B_frugal'!$B$185 | J13: ='B_frugal'!$B$186 | K13: ='B_frugal'!$B$187 | L13: ='B_frugal'!$B$190 | M13: ='B_frugal'!$B$191 | N13: ='B_frugal'!$B$188 | O13: ='B_frugal'!$B$189 | P13: ='B_frugal'!$B$192 | Q13: ='B_frugal'!$B$193 | R13: ='B_frugal'!$B$194
A14: B_frugal_sans_dette | B14: ='B_frugal_sans_dette'!$B$178 | C14: ='B_frugal_sans_dette'!$B$179 | D14: ='B_frugal_sans_dette'!$B$180 | E14: ='B_frugal_sans_dette'!$B$181 | F14: ='B_frugal_sans_dette'!$B$182 | G14: ='B_frugal_sans_dette'!$B$183 | H14: ='B_frugal_sans_dette'!$B$184 | I14: ='B_frugal_sans_dette'!$B$185 | J14: ='B_frugal_sans_dette'!$B$186 | K14: ='B_frugal_sans_dette'!$B$187 | L14: ='B_frugal_sans_dette'!$B$190 | M14: ='B_frugal_sans_dette'!$B$191 | N14: ='B_frugal_sans_dette'!$B$188 | O14: ='B_frugal_sans_dette'!$B$189 | P14: ='B_frugal_sans_dette'!$B$192 | Q14: ='B_frugal_sans_dette'!$B$193 | R14: ='B_frugal_sans_dette'!$B$194
A15: A_frugal | B15: ='A_frugal'!$B$180 | C15: ='A_frugal'!$B$181 | D15: ='A_frugal'!$B$182 | E15: ='A_frugal'!$B$183 | F15: ='A_frugal'!$B$184 | G15: ='A_frugal'!$B$185 | H15: ='A_frugal'!$B$186 | I15: ='A_frugal'!$B$187 | J15: ='A_frugal'!$B$188 | K15: ='A_frugal'!$B$189 | L15: ='A_frugal'!$B$192 | M15: ='A_frugal'!$B$193 | N15: ='A_frugal'!$B$190 | O15: ='A_frugal'!$B$191 | P15: ='A_frugal'!$B$194 | Q15: ='A_frugal'!$B$195 | R15: ='A_frugal'!$B$196
A16: C_central | B16: ='C_central'!$B$178 | C16: ='C_central'!$B$179 | D16: ='C_central'!$B$180 | E16: ='C_central'!$B$181 | F16: ='C_central'!$B$182 | G16: ='C_central'!$B$183 | H16: ='C_central'!$B$184 | I16: ='C_central'!$B$185 | J16: ='C_central'!$B$186 | K16: ='C_central'!$B$187 | L16: ='C_central'!$B$190 | M16: ='C_central'!$B$191 | N16: ='C_central'!$B$188 | O16: ='C_central'!$B$189 | P16: ='C_central'!$B$192 | Q16: ='C_central'!$B$193 | R16: ='C_central'!$B$194
A17: C_prudent | B17: ='C_prudent'!$B$178 | C17: ='C_prudent'!$B$179 | D17: ='C_prudent'!$B$180 | E17: ='C_prudent'!$B$181 | F17: ='C_prudent'!$B$182 | G17: ='C_prudent'!$B$183 | H17: ='C_prudent'!$B$184 | I17: ='C_prudent'!$B$185 | J17: ='C_prudent'!$B$186 | K17: ='C_prudent'!$B$187 | L17: ='C_prudent'!$B$190 | M17: ='C_prudent'!$B$191 | N17: ='C_prudent'!$B$188 | O17: ='C_prudent'!$B$189 | P17: ='C_prudent'!$B$192 | Q17: ='C_prudent'!$B$193 | R17: ='C_prudent'!$B$194
A18: C_optimiste | B18: ='C_optimiste'!$B$178 | C18: ='C_optimiste'!$B$179 | D18: ='C_optimiste'!$B$180 | E18: ='C_optimiste'!$B$181 | F18: ='C_optimiste'!$B$182 | G18: ='C_optimiste'!$B$183 | H18: ='C_optimiste'!$B$184 | I18: ='C_optimiste'!$B$185 | J18: ='C_optimiste'!$B$186 | K18: ='C_optimiste'!$B$187 | L18: ='C_optimiste'!$B$190 | M18: ='C_optimiste'!$B$191 | N18: ='C_optimiste'!$B$188 | O18: ='C_optimiste'!$B$189 | P18: ='C_optimiste'!$B$192 | Q18: ='C_optimiste'!$B$193 | R18: ='C_optimiste'!$B$194
A19: C_negocie | B19: ='C_negocie'!$B$178 | C19: ='C_negocie'!$B$179 | D19: ='C_negocie'!$B$180 | E19: ='C_negocie'!$B$181 | F19: ='C_negocie'!$B$182 | G19: ='C_negocie'!$B$183 | H19: ='C_negocie'!$B$184 | I19: ='C_negocie'!$B$185 | J19: ='C_negocie'!$B$186 | K19: ='C_negocie'!$B$187 | L19: ='C_negocie'!$B$190 | M19: ='C_negocie'!$B$191 | N19: ='C_negocie'!$B$188 | O19: ='C_negocie'!$B$189 | P19: ='C_negocie'!$B$192 | Q19: ='C_negocie'!$B$193 | R19: ='C_negocie'!$B$194
A20: C_holding_realiste | B20: ='C_holding_realiste'!$B$178 | C20: ='C_holding_realiste'!$B$179 | D20: ='C_holding_realiste'!$B$180 | E20: ='C_holding_realiste'!$B$181 | F20: ='C_holding_realiste'!$B$182 | G20: ='C_holding_realiste'!$B$183 | H20: ='C_holding_realiste'!$B$184 | I20: ='C_holding_realiste'!$B$185 | J20: ='C_holding_realiste'!$B$186 | K20: ='C_holding_realiste'!$B$187 | L20: ='C_holding_realiste'!$B$190 | M20: ='C_holding_realiste'!$B$191 | N20: ='C_holding_realiste'!$B$188 | O20: ='C_holding_realiste'!$B$189 | P20: ='C_holding_realiste'!$B$192 | Q20: ='C_holding_realiste'!$B$193 | R20: ='C_holding_realiste'!$B$194
A21: D_chateau_modeste | B21: ='D_chateau_modeste'!$B$176 | C21: ='D_chateau_modeste'!$B$177 | D21: ='D_chateau_modeste'!$B$178 | E21: ='D_chateau_modeste'!$B$179 | F21: ='D_chateau_modeste'!$B$180 | G21: ='D_chateau_modeste'!$B$181 | H21: ='D_chateau_modeste'!$B$182 | I21: ='D_chateau_modeste'!$B$183 | J21: ='D_chateau_modeste'!$B$184 | K21: ='D_chateau_modeste'!$B$185 | L21: ='D_chateau_modeste'!$B$188 | M21: ='D_chateau_modeste'!$B$189 | N21: ='D_chateau_modeste'!$B$186 | O21: ='D_chateau_modeste'!$B$187 | P21: ='D_chateau_modeste'!$B$190 | Q21: ='D_chateau_modeste'!$B$191 | R21: ='D_chateau_modeste'!$B$192
A22: E_bail_emphyteotique | B22: ='E_bail_emphyteotique'!$B$180 | C22: ='E_bail_emphyteotique'!$B$181 | D22: ='E_bail_emphyteotique'!$B$182 | E22: ='E_bail_emphyteotique'!$B$183 | F22: ='E_bail_emphyteotique'!$B$184 | G22: ='E_bail_emphyteotique'!$B$185 | H22: ='E_bail_emphyteotique'!$B$186 | I22: ='E_bail_emphyteotique'!$B$187 | J22: ='E_bail_emphyteotique'!$B$188 | K22: ='E_bail_emphyteotique'!$B$189 | L22: ='E_bail_emphyteotique'!$B$192 | M22: ='E_bail_emphyteotique'!$B$193 | N22: ='E_bail_emphyteotique'!$B$190 | O22: ='E_bail_emphyteotique'!$B$191 | P22: ='E_bail_emphyteotique'!$B$194 | Q22: ='E_bail_emphyteotique'!$B$195 | R22: ='E_bail_emphyteotique'!$B$196
A23: E_allege | B23: ='E_allege'!$B$180 | C23: ='E_allege'!$B$181 | D23: ='E_allege'!$B$182 | E23: ='E_allege'!$B$183 | F23: ='E_allege'!$B$184 | G23: ='E_allege'!$B$185 | H23: ='E_allege'!$B$186 | I23: ='E_allege'!$B$187 | J23: ='E_allege'!$B$188 | K23: ='E_allege'!$B$189 | L23: ='E_allege'!$B$192 | M23: ='E_allege'!$B$193 | N23: ='E_allege'!$B$190 | O23: ='E_allege'!$B$191 | P23: ='E_allege'!$B$194 | Q23: ='E_allege'!$B$195 | R23: ='E_allege'!$B$196
A24: S_Cc_CA-30 | B24: ='S_Cc_CA-30'!$B$178 | C24: ='S_Cc_CA-30'!$B$179 | D24: ='S_Cc_CA-30'!$B$180 | E24: ='S_Cc_CA-30'!$B$181 | F24: ='S_Cc_CA-30'!$B$182 | G24: ='S_Cc_CA-30'!$B$183 | H24: ='S_Cc_CA-30'!$B$184 | I24: ='S_Cc_CA-30'!$B$185 | J24: ='S_Cc_CA-30'!$B$186 | K24: ='S_Cc_CA-30'!$B$187 | L24: ='S_Cc_CA-30'!$B$190 | M24: ='S_Cc_CA-30'!$B$191 | N24: ='S_Cc_CA-30'!$B$188 | O24: ='S_Cc_CA-30'!$B$189 | P24: ='S_Cc_CA-30'!$B$192 | Q24: ='S_Cc_CA-30'!$B$193 | R24: ='S_Cc_CA-30'!$B$194
A25: S_Cc_Travaux+30 | B25: ='S_Cc_Travaux+30'!$B$178 | C25: ='S_Cc_Travaux+30'!$B$179 | D25: ='S_Cc_Travaux+30'!$B$180 | E25: ='S_Cc_Travaux+30'!$B$181 | F25: ='S_Cc_Travaux+30'!$B$182 | G25: ='S_Cc_Travaux+30'!$B$183 | H25: ='S_Cc_Travaux+30'!$B$184 | I25: ='S_Cc_Travaux+30'!$B$185 | J25: ='S_Cc_Travaux+30'!$B$186 | K25: ='S_Cc_Travaux+30'!$B$187 | L25: ='S_Cc_Travaux+30'!$B$190 | M25: ='S_Cc_Travaux+30'!$B$191 | N25: ='S_Cc_Travaux+30'!$B$188 | O25: ='S_Cc_Travaux+30'!$B$189 | P25: ='S_Cc_Travaux+30'!$B$192 | Q25: ='S_Cc_Travaux+30'!$B$193 | R25: ='S_Cc_Travaux+30'!$B$194
A26: S_Cc_Retard12m | B26: ='S_Cc_Retard12m'!$B$178 | C26: ='S_Cc_Retard12m'!$B$179 | D26: ='S_Cc_Retard12m'!$B$180 | E26: ='S_Cc_Retard12m'!$B$181 | F26: ='S_Cc_Retard12m'!$B$182 | G26: ='S_Cc_Retard12m'!$B$183 | H26: ='S_Cc_Retard12m'!$B$184 | I26: ='S_Cc_Retard12m'!$B$185 | J26: ='S_Cc_Retard12m'!$B$186 | K26: ='S_Cc_Retard12m'!$B$187 | L26: ='S_Cc_Retard12m'!$B$190 | M26: ='S_Cc_Retard12m'!$B$191 | N26: ='S_Cc_Retard12m'!$B$188 | O26: ='S_Cc_Retard12m'!$B$189 | P26: ='S_Cc_Retard12m'!$B$192 | Q26: ='S_Cc_Retard12m'!$B$193 | R26: ='S_Cc_Retard12m'!$B$194
A27: S_Cc_Taux+2pts | B27: ='S_Cc_Taux+2pts'!$B$178 | C27: ='S_Cc_Taux+2pts'!$B$179 | D27: ='S_Cc_Taux+2pts'!$B$180 | E27: ='S_Cc_Taux+2pts'!$B$181 | F27: ='S_Cc_Taux+2pts'!$B$182 | G27: ='S_Cc_Taux+2pts'!$B$183 | H27: ='S_Cc_Taux+2pts'!$B$184 | I27: ='S_Cc_Taux+2pts'!$B$185 | J27: ='S_Cc_Taux+2pts'!$B$186 | K27: ='S_Cc_Taux+2pts'!$B$187 | L27: ='S_Cc_Taux+2pts'!$B$190 | M27: ='S_Cc_Taux+2pts'!$B$191 | N27: ='S_Cc_Taux+2pts'!$B$188 | O27: ='S_Cc_Taux+2pts'!$B$189 | P27: ='S_Cc_Taux+2pts'!$B$192 | Q27: ='S_Cc_Taux+2pts'!$B$193 | R27: ='S_Cc_Taux+2pts'!$B$194
A28: S_Cc_RetraitFP50 | B28: ='S_Cc_RetraitFP50'!$B$178 | C28: ='S_Cc_RetraitFP50'!$B$179 | D28: ='S_Cc_RetraitFP50'!$B$180 | E28: ='S_Cc_RetraitFP50'!$B$181 | F28: ='S_Cc_RetraitFP50'!$B$182 | G28: ='S_Cc_RetraitFP50'!$B$183 | H28: ='S_Cc_RetraitFP50'!$B$184 | I28: ='S_Cc_RetraitFP50'!$B$185 | J28: ='S_Cc_RetraitFP50'!$B$186 | K28: ='S_Cc_RetraitFP50'!$B$187 | L28: ='S_Cc_RetraitFP50'!$B$190 | M28: ='S_Cc_RetraitFP50'!$B$191 | N28: ='S_Cc_RetraitFP50'!$B$188 | O28: ='S_Cc_RetraitFP50'!$B$189 | P28: ='S_Cc_RetraitFP50'!$B$192 | Q28: ='S_Cc_RetraitFP50'!$B$193 | R28: ='S_Cc_RetraitFP50'!$B$194
A29: S_Cc_Annul40evt | B29: ='S_Cc_Annul40evt'!$B$178 | C29: ='S_Cc_Annul40evt'!$B$179 | D29: ='S_Cc_Annul40evt'!$B$180 | E29: ='S_Cc_Annul40evt'!$B$181 | F29: ='S_Cc_Annul40evt'!$B$182 | G29: ='S_Cc_Annul40evt'!$B$183 | H29: ='S_Cc_Annul40evt'!$B$184 | I29: ='S_Cc_Annul40evt'!$B$185 | J29: ='S_Cc_Annul40evt'!$B$186 | K29: ='S_Cc_Annul40evt'!$B$187 | L29: ='S_Cc_Annul40evt'!$B$190 | M29: ='S_Cc_Annul40evt'!$B$191 | N29: ='S_Cc_Annul40evt'!$B$188 | O29: ='S_Cc_Annul40evt'!$B$189 | P29: ='S_Cc_Annul40evt'!$B$192 | Q29: ='S_Cc_Annul40evt'!$B$193 | R29: ='S_Cc_Annul40evt'!$B$194
A30: S_Cc_Cumul | B30: ='S_Cc_Cumul'!$B$178 | C30: ='S_Cc_Cumul'!$B$179 | D30: ='S_Cc_Cumul'!$B$180 | E30: ='S_Cc_Cumul'!$B$181 | F30: ='S_Cc_Cumul'!$B$182 | G30: ='S_Cc_Cumul'!$B$183 | H30: ='S_Cc_Cumul'!$B$184 | I30: ='S_Cc_Cumul'!$B$185 | J30: ='S_Cc_Cumul'!$B$186 | K30: ='S_Cc_Cumul'!$B$187 | L30: ='S_Cc_Cumul'!$B$190 | M30: ='S_Cc_Cumul'!$B$191 | N30: ='S_Cc_Cumul'!$B$188 | O30: ='S_Cc_Cumul'!$B$189 | P30: ='S_Cc_Cumul'!$B$192 | Q30: ='S_Cc_Cumul'!$B$193 | R30: ='S_Cc_Cumul'!$B$194
A31: S_Cn_CA-30 | B31: ='S_Cn_CA-30'!$B$178 | C31: ='S_Cn_CA-30'!$B$179 | D31: ='S_Cn_CA-30'!$B$180 | E31: ='S_Cn_CA-30'!$B$181 | F31: ='S_Cn_CA-30'!$B$182 | G31: ='S_Cn_CA-30'!$B$183 | H31: ='S_Cn_CA-30'!$B$184 | I31: ='S_Cn_CA-30'!$B$185 | J31: ='S_Cn_CA-30'!$B$186 | K31: ='S_Cn_CA-30'!$B$187 | L31: ='S_Cn_CA-30'!$B$190 | M31: ='S_Cn_CA-30'!$B$191 | N31: ='S_Cn_CA-30'!$B$188 | O31: ='S_Cn_CA-30'!$B$189 | P31: ='S_Cn_CA-30'!$B$192 | Q31: ='S_Cn_CA-30'!$B$193 | R31: ='S_Cn_CA-30'!$B$194
A32: S_Cn_Travaux+30 | B32: ='S_Cn_Travaux+30'!$B$178 | C32: ='S_Cn_Travaux+30'!$B$179 | D32: ='S_Cn_Travaux+30'!$B$180 | E32: ='S_Cn_Travaux+30'!$B$181 | F32: ='S_Cn_Travaux+30'!$B$182 | G32: ='S_Cn_Travaux+30'!$B$183 | H32: ='S_Cn_Travaux+30'!$B$184 | I32: ='S_Cn_Travaux+30'!$B$185 | J32: ='S_Cn_Travaux+30'!$B$186 | K32: ='S_Cn_Travaux+30'!$B$187 | L32: ='S_Cn_Travaux+30'!$B$190 | M32: ='S_Cn_Travaux+30'!$B$191 | N32: ='S_Cn_Travaux+30'!$B$188 | O32: ='S_Cn_Travaux+30'!$B$189 | P32: ='S_Cn_Travaux+30'!$B$192 | Q32: ='S_Cn_Travaux+30'!$B$193 | R32: ='S_Cn_Travaux+30'!$B$194
A33: S_Cn_Retard12m | B33: ='S_Cn_Retard12m'!$B$178 | C33: ='S_Cn_Retard12m'!$B$179 | D33: ='S_Cn_Retard12m'!$B$180 | E33: ='S_Cn_Retard12m'!$B$181 | F33: ='S_Cn_Retard12m'!$B$182 | G33: ='S_Cn_Retard12m'!$B$183 | H33: ='S_Cn_Retard12m'!$B$184 | I33: ='S_Cn_Retard12m'!$B$185 | J33: ='S_Cn_Retard12m'!$B$186 | K33: ='S_Cn_Retard12m'!$B$187 | L33: ='S_Cn_Retard12m'!$B$190 | M33: ='S_Cn_Retard12m'!$B$191 | N33: ='S_Cn_Retard12m'!$B$188 | O33: ='S_Cn_Retard12m'!$B$189 | P33: ='S_Cn_Retard12m'!$B$192 | Q33: ='S_Cn_Retard12m'!$B$193 | R33: ='S_Cn_Retard12m'!$B$194
A34: S_Cn_Taux+2pts | B34: ='S_Cn_Taux+2pts'!$B$178 | C34: ='S_Cn_Taux+2pts'!$B$179 | D34: ='S_Cn_Taux+2pts'!$B$180 | E34: ='S_Cn_Taux+2pts'!$B$181 | F34: ='S_Cn_Taux+2pts'!$B$182 | G34: ='S_Cn_Taux+2pts'!$B$183 | H34: ='S_Cn_Taux+2pts'!$B$184 | I34: ='S_Cn_Taux+2pts'!$B$185 | J34: ='S_Cn_Taux+2pts'!$B$186 | K34: ='S_Cn_Taux+2pts'!$B$187 | L34: ='S_Cn_Taux+2pts'!$B$190 | M34: ='S_Cn_Taux+2pts'!$B$191 | N34: ='S_Cn_Taux+2pts'!$B$188 | O34: ='S_Cn_Taux+2pts'!$B$189 | P34: ='S_Cn_Taux+2pts'!$B$192 | Q34: ='S_Cn_Taux+2pts'!$B$193 | R34: ='S_Cn_Taux+2pts'!$B$194
A35: S_Cn_RetraitFP50 | B35: ='S_Cn_RetraitFP50'!$B$178 | C35: ='S_Cn_RetraitFP50'!$B$179 | D35: ='S_Cn_RetraitFP50'!$B$180 | E35: ='S_Cn_RetraitFP50'!$B$181 | F35: ='S_Cn_RetraitFP50'!$B$182 | G35: ='S_Cn_RetraitFP50'!$B$183 | H35: ='S_Cn_RetraitFP50'!$B$184 | I35: ='S_Cn_RetraitFP50'!$B$185 | J35: ='S_Cn_RetraitFP50'!$B$186 | K35: ='S_Cn_RetraitFP50'!$B$187 | L35: ='S_Cn_RetraitFP50'!$B$190 | M35: ='S_Cn_RetraitFP50'!$B$191 | N35: ='S_Cn_RetraitFP50'!$B$188 | O35: ='S_Cn_RetraitFP50'!$B$189 | P35: ='S_Cn_RetraitFP50'!$B$192 | Q35: ='S_Cn_RetraitFP50'!$B$193 | R35: ='S_Cn_RetraitFP50'!$B$194
A36: S_Cn_Annul40evt | B36: ='S_Cn_Annul40evt'!$B$178 | C36: ='S_Cn_Annul40evt'!$B$179 | D36: ='S_Cn_Annul40evt'!$B$180 | E36: ='S_Cn_Annul40evt'!$B$181 | F36: ='S_Cn_Annul40evt'!$B$182 | G36: ='S_Cn_Annul40evt'!$B$183 | H36: ='S_Cn_Annul40evt'!$B$184 | I36: ='S_Cn_Annul40evt'!$B$185 | J36: ='S_Cn_Annul40evt'!$B$186 | K36: ='S_Cn_Annul40evt'!$B$187 | L36: ='S_Cn_Annul40evt'!$B$190 | M36: ='S_Cn_Annul40evt'!$B$191 | N36: ='S_Cn_Annul40evt'!$B$188 | O36: ='S_Cn_Annul40evt'!$B$189 | P36: ='S_Cn_Annul40evt'!$B$192 | Q36: ='S_Cn_Annul40evt'!$B$193 | R36: ='S_Cn_Annul40evt'!$B$194
A37: S_Cn_Cumul | B37: ='S_Cn_Cumul'!$B$178 | C37: ='S_Cn_Cumul'!$B$179 | D37: ='S_Cn_Cumul'!$B$180 | E37: ='S_Cn_Cumul'!$B$181 | F37: ='S_Cn_Cumul'!$B$182 | G37: ='S_Cn_Cumul'!$B$183 | H37: ='S_Cn_Cumul'!$B$184 | I37: ='S_Cn_Cumul'!$B$185 | J37: ='S_Cn_Cumul'!$B$186 | K37: ='S_Cn_Cumul'!$B$187 | L37: ='S_Cn_Cumul'!$B$190 | M37: ='S_Cn_Cumul'!$B$191 | N37: ='S_Cn_Cumul'!$B$188 | O37: ='S_Cn_Cumul'!$B$189 | P37: ='S_Cn_Cumul'!$B$192 | Q37: ='S_Cn_Cumul'!$B$193 | R37: ='S_Cn_Cumul'!$B$194
A38: S_Bfsd_CA-30 | B38: ='S_Bfsd_CA-30'!$B$178 | C38: ='S_Bfsd_CA-30'!$B$179 | D38: ='S_Bfsd_CA-30'!$B$180 | E38: ='S_Bfsd_CA-30'!$B$181 | F38: ='S_Bfsd_CA-30'!$B$182 | G38: ='S_Bfsd_CA-30'!$B$183 | H38: ='S_Bfsd_CA-30'!$B$184 | I38: ='S_Bfsd_CA-30'!$B$185 | J38: ='S_Bfsd_CA-30'!$B$186 | K38: ='S_Bfsd_CA-30'!$B$187 | L38: ='S_Bfsd_CA-30'!$B$190 | M38: ='S_Bfsd_CA-30'!$B$191 | N38: ='S_Bfsd_CA-30'!$B$188 | O38: ='S_Bfsd_CA-30'!$B$189 | P38: ='S_Bfsd_CA-30'!$B$192 | Q38: ='S_Bfsd_CA-30'!$B$193 | R38: ='S_Bfsd_CA-30'!$B$194
A39: S_Bfsd_Travaux+30 | B39: ='S_Bfsd_Travaux+30'!$B$178 | C39: ='S_Bfsd_Travaux+30'!$B$179 | D39: ='S_Bfsd_Travaux+30'!$B$180 | E39: ='S_Bfsd_Travaux+30'!$B$181 | F39: ='S_Bfsd_Travaux+30'!$B$182 | G39: ='S_Bfsd_Travaux+30'!$B$183 | H39: ='S_Bfsd_Travaux+30'!$B$184 | I39: ='S_Bfsd_Travaux+30'!$B$185 | J39: ='S_Bfsd_Travaux+30'!$B$186 | K39: ='S_Bfsd_Travaux+30'!$B$187 | L39: ='S_Bfsd_Travaux+30'!$B$190 | M39: ='S_Bfsd_Travaux+30'!$B$191 | N39: ='S_Bfsd_Travaux+30'!$B$188 | O39: ='S_Bfsd_Travaux+30'!$B$189 | P39: ='S_Bfsd_Travaux+30'!$B$192 | Q39: ='S_Bfsd_Travaux+30'!$B$193 | R39: ='S_Bfsd_Travaux+30'!$B$194
A40: S_Bfsd_Retard12m | B40: ='S_Bfsd_Retard12m'!$B$178 | C40: ='S_Bfsd_Retard12m'!$B$179 | D40: ='S_Bfsd_Retard12m'!$B$180 | E40: ='S_Bfsd_Retard12m'!$B$181 | F40: ='S_Bfsd_Retard12m'!$B$182 | G40: ='S_Bfsd_Retard12m'!$B$183 | H40: ='S_Bfsd_Retard12m'!$B$184 | I40: ='S_Bfsd_Retard12m'!$B$185 | J40: ='S_Bfsd_Retard12m'!$B$186 | K40: ='S_Bfsd_Retard12m'!$B$187 | L40: ='S_Bfsd_Retard12m'!$B$190 | M40: ='S_Bfsd_Retard12m'!$B$191 | N40: ='S_Bfsd_Retard12m'!$B$188 | O40: ='S_Bfsd_Retard12m'!$B$189 | P40: ='S_Bfsd_Retard12m'!$B$192 | Q40: ='S_Bfsd_Retard12m'!$B$193 | R40: ='S_Bfsd_Retard12m'!$B$194
A41: S_Bfsd_Taux+2pts | B41: ='S_Bfsd_Taux+2pts'!$B$178 | C41: ='S_Bfsd_Taux+2pts'!$B$179 | D41: ='S_Bfsd_Taux+2pts'!$B$180 | E41: ='S_Bfsd_Taux+2pts'!$B$181 | F41: ='S_Bfsd_Taux+2pts'!$B$182 | G41: ='S_Bfsd_Taux+2pts'!$B$183 | H41: ='S_Bfsd_Taux+2pts'!$B$184 | I41: ='S_Bfsd_Taux+2pts'!$B$185 | J41: ='S_Bfsd_Taux+2pts'!$B$186 | K41: ='S_Bfsd_Taux+2pts'!$B$187 | L41: ='S_Bfsd_Taux+2pts'!$B$190 | M41: ='S_Bfsd_Taux+2pts'!$B$191 | N41: ='S_Bfsd_Taux+2pts'!$B$188 | O41: ='S_Bfsd_Taux+2pts'!$B$189 | P41: ='S_Bfsd_Taux+2pts'!$B$192 | Q41: ='S_Bfsd_Taux+2pts'!$B$193 | R41: ='S_Bfsd_Taux+2pts'!$B$194
...

Sheet A_central
A1: Scénario A — Château équestre « sport » — cas central
A2: Cellules jaunes/bleues = hypothèses éditables. Tout le reste est calculé. Colonne D (bloc hypothèses) = source ou statut (ESTIMATION = non vérifiée).
A4: 1. Calendrier, acquisition et travaux
A5: Année d'acquisition des murs (1 = immédiate) | B5: 1 | C5: année | D5: Achat immédiat (2027)
A6: Année d'ouverture commerciale (avant stress) | B6: 2 | C6: année | D6: Année 1 = travaux ; EST
A7: Prix d'acquisition | B7: 2500000 | C7: € | D7: PL : médiane de 19 annonces de châteaux ≥ 30 ha (quartiles 1,29-3,07 M€) [A1]
A8: Frais d'acquisition (droits + notaire) | B8: 0.075 | C8: % | D8: EST : DMTO ≈ 5,8-6,3 % + notaire ≈ 1,2 % ; vente SAFER : frais 8,4 % TTC mais exonération de droits possible [A1, PL]
A9: Part du prix affectable au bâti (amortissable) | B9: 0.55 | C9: % | D9: EST
A10: Travaux de restauration / mise aux normes | B10: 500000 | C10: € | D10: EST sans visite : top 5 des biens équipés 0,1-0,7 M€ [A1]
A11: Investissements équestres (boxes, carrière, manège…) | B11: 350000 | C11: € | D11: EST : marcheur 35 k€, carrière 35 €/m², barn 200 €/m² (PL [A3 H19]) + 10 box supplémentaires
A12: Investissements événementiel / hébergement | B12: 80000 | C12: € | D12: EST : salon de réception pour ventes privées, pas de salle ERP > 50 pers.
A13: Répartition travaux : année d'acquisition | B13: 0.6 | C13: % | D13: EST
A14: Répartition travaux : année +1 | B14: 0.3 | C14: % | D14: EST
A15: Répartition travaux : année +2 | B15: 0.1 | C15: % | D15: EST
A16: Gros entretien patrimonial annuel (% prix+travaux) | B16: 0.018 | C16: % | D16: ≈ 41 k€/an sur (bâti + travaux) : Demeure Historique ≥ 40 k€/an hors restauration (PL [A8]) ; Barnes 20-80 k€/an [A4 §11] ; démarre en année d'acquisition + 3
... A20: Loyer de la partie privée payé par le fondateur (hors CA d'exploitation) | B20: 0 | C20: € | D20: Correction audit M1 : aucun loyer privé compté — le logis doit être détenu à part (SCI à l'IR, hors taxe 235 ter C [A6]) et payé par le fondateur personnellement
A22: 2. Financement
A23: Apport du fondateur (année 1) | B23: 1000000 | C23: € | D23: Scénario d'apport S3 (hypothèse ; apport réel inconnu)
A24: Fonds propres apportés à l'acquisition (investisseurs ou holding) | B24: 0 | C24: € | D24: Aucun investisseur
A25: Ces fonds propres viennent-ils de la holding du fondateur ? (1/0) | B25: 0
A26: Subventions (non acquises : 0 par défaut) | B26: 0 | C26: € | D26: Aucune subvention considérée comme acquise
A27: Dette bancaire (année d'acquisition) | B27: 2400000 | C27: € | D27: NON ACQUIS — montage 1 [A2] : prêt hypothécaire 20 ans ; LTV ≈ 70 %, jugée trop élevée par l'agent 2
A28: Taux de la dette bancaire | B28: 0.04 | C28: % | D28: PL : nouveaux crédits PME 3,64 % (FBF, 06/2026) ; EX : 3,66 % (BdF, 08/2026) ; retenu 4,0 % [A2]
A29: Durée dette bancaire | B29: 20 | C29: ans | D29: A2 (Bpifrance : 15 ans avec hypothèque, PL)
A30: Différé d'amortissement (dans la durée) | B30: 1 | C30: ans | D30: EST
A31: Crédit-vendeur | B31: 0 | C31: €
A32: Taux crédit-vendeur | B32: 0.03 | C32: % | D32: EST
A33: Durée crédit-vendeur (amortissable) | B33: 12 | C33: ans | D33: EST
A34: Obligations / quasi-fonds propres (in fine) | B34: 0 | C34: €
A35: Coupon annuel des obligations | B35: 0.07 | C35: % | D35: PL : obligations Château Fontenay 7 % [A2]
A36: Année de remboursement des obligations | B36: 6 | C36: année | D36: EST
A37: Part de capital supplémentaire accordée au fondateur pour son travail (sweat equity) | B37: 0 | C37: % | D37: Fondateur seul
A38: Droits de vote du fondateur | B38: 1 | C38: %
A39: Réserve de liquidité cible | B39: 150000 | C39: € | D39: EST
A40: TRI minimal exigé par des investisseurs extérieurs | B40: 0.06 | C40: % | D40: EST : rendement minimal d'un investisseur en fonds propres illiquide (Anaxago affiche 8,7 % net, PL [A2])
A41: Le dirigeant est-il rémunéré par le domaine ? (1/0) | B41: 1 | D41: Rémunération du dirigeant incluse
A42: Part du capital du fondateur (calculée : apports au prorata + prime d'industrie, plafonnée à 100 %) | B42: =MIN(1,($B$23+$B$24*$B$25)/MAX(1,$B$23+$B$24)+$B$37)
A44: 3. Paramètres de stress (neutres = 100 % / 0)
A45: Multiplicateur de chiffre d'affaires | B45: 1 | C45: % | D45: neutre
A46: Multiplicateur du budget travaux | B46: 1 | C46: % | D46: neutre
...

Sheet A_prudent
A1: Scénario A — Château équestre « sport » — cas prudent
A2: Cellules jaunes/bleues = hypothèses éditables. Tout le reste est calculé. Colonne D (bloc hypothèses) = source ou statut (ESTIMATION = non vérifiée).
A4: 1. Calendrier, acquisition et travaux
A5: Année d'acquisition des murs (1 = immédiate) | B5: 1 | C5: année | D5: Achat immédiat (2027)
A6: Année d'ouverture commerciale (avant stress) | B6: 2 | C6: année | D6: Année 1 = travaux ; EST
A7: Prix d'acquisition | B7: 2500000 | C7: € | D7: PL : médiane de 19 annonces de châteaux ≥ 30 ha (quartiles 1,29-3,07 M€) [A1]
A8: Frais d'acquisition (droits + notaire) | B8: 0.075 | C8: % | D8: EST : DMTO ≈ 5,8-6,3 % + notaire ≈ 1,2 % ; vente SAFER : frais 8,4 % TTC mais exonération de droits possible [A1, PL]
A9: Part du prix affectable au bâti (amortissable) | B9: 0.55 | C9: % | D9: EST
A10: Travaux de restauration / mise aux normes | B10: 625000 | C10: € | D10: EST sans visite : top 5 des biens équipés 0,1-0,7 M€ [A1]
A11: Investissements équestres (boxes, carrière, manège…) | B11: 437500 | C11: € | D11: EST : marcheur 35 k€, carrière 35 €/m², barn 200 €/m² (PL [A3 H19]) + 10 box supplémentaires
A12: Investissements événementiel / hébergement | B12: 100000 | C12: € | D12: EST : salon de réception pour ventes privées, pas de salle ERP > 50 pers.
A13: Répartition travaux : année d'acquisition | B13: 0.6 | C13: % | D13: EST
A14: Répartition travaux : année +1 | B14: 0.3 | C14: % | D14: EST
A15: Répartition travaux : année +2 | B15: 0.1 | C15: % | D15: EST
A16: Gros entretien patrimonial annuel (% prix+travaux) | B16: 0.018 | C16: % | D16: ≈ 41 k€/an sur (bâti + travaux) : Demeure Historique ≥ 40 k€/an hors restauration (PL [A8]) ; Barnes 20-80 k€/an [A4 §11] ; démarre en année d'acquisition + 3
... A20: Loyer de la partie privée payé par le fondateur (hors CA d'exploitation) | B20: 0 | C20: € | D20: Correction audit M1 : aucun loyer privé compté — le logis doit être détenu à part (SCI à l'IR, hors taxe 235 ter C [A6]) et payé par le fondateur personnellement
A22: 2. Financement
A23: Apport du fondateur (année 1) | B23: 1000000 | C23: € | D23: Scénario d'apport S3 (hypothèse ; apport réel inconnu)
A24: Fonds propres apportés à l'acquisition (investisseurs ou holding) | B24: 0 | C24: € | D24: Aucun investisseur
A25: Ces fonds propres viennent-ils de la holding du fondateur ? (1/0) | B25: 0
A26: Subventions (non acquises : 0 par défaut) | B26: 0 | C26: € | D26: Aucune subvention considérée comme acquise
A27: Dette bancaire (année d'acquisition) | B27: 2400000 | C27: € | D27: NON ACQUIS — montage 1 [A2] : prêt hypothécaire 20 ans ; LTV ≈ 70 %, jugée trop élevée par l'agent 2
A28: Taux de la dette bancaire | B28: 0.04 | C28: % | D28: PL : nouveaux crédits PME 3,64 % (FBF, 06/2026) ; EX : 3,66 % (BdF, 08/2026) ; retenu 4,0 % [A2]
A29: Durée dette bancaire | B29: 20 | C29: ans | D29: A2 (Bpifrance : 15 ans avec hypothèque, PL)
A30: Différé d'amortissement (dans la durée) | B30: 1 | C30: ans | D30: EST
A31: Crédit-vendeur | B31: 0 | C31: €
A32: Taux crédit-vendeur | B32: 0.03 | C32: % | D32: EST
A33: Durée crédit-vendeur (amortissable) | B33: 12 | C33: ans | D33: EST
A34: Obligations / quasi-fonds propres (in fine) | B34: 0 | C34: €
A35: Coupon annuel des obligations | B35: 0.07 | C35: % | D35: PL : obligations Château Fontenay 7 % [A2]
A36: Année de remboursement des obligations | B36: 6 | C36: année | D36: EST
A37: Part de capital supplémentaire accordée au fondateur pour son travail (sweat equity) | B37: 0 | C37: % | D37: Fondateur seul
A38: Droits de vote du fondateur | B38: 1 | C38: %
A39: Réserve de liquidité cible | B39: 150000 | C39: € | D39: EST
A40: TRI minimal exigé par des investisseurs extérieurs | B40: 0.06 | C40: % | D40: EST : rendement minimal d'un investisseur en fonds propres illiquide (Anaxago affiche 8,7 % net, PL [A2])
A41: Le dirigeant est-il rémunéré par le domaine ? (1/0) | B41: 1 | D41: Rémunération du dirigeant incluse
A42: Part du capital du fondateur (calculée : apports au prorata + prime d'industrie, plafonnée à 100 %) | B42: =MIN(1,($B$23+$B$24*$B$25)/MAX(1,$B$23+$B$24)+$B$37)
A44: 3. Paramètres de stress (neutres = 100 % / 0)
A45: Multiplicateur de chiffre d'affaires | B45: 1 | C45: % | D45: neutre
A46: Multiplicateur du budget travaux | B46: 1 | C46: % | D46: neutre
...

Sheet A_optimiste
A1: Scénario A — Château équestre « sport » — cas optimiste
A2: Cellules jaunes/bleues = hypothèses éditables. Tout le reste est calculé. Colonne D (bloc hypothèses) = source ou statut (ESTIMATION = non vérifiée).
A4: 1. Calendrier, acquisition et travaux
A5: Année d'acquisition des murs (1 = immédiate) | B5: 1 | C5: année | D5: Achat immédiat (2027)
A6: Année d'ouverture commerciale (avant stress) | B6: 2 | C6: année | D6: Année 1 = travaux ; EST
A7: Prix d'acquisition | B7: 2500000 | C7: € | D7: PL : médiane de 19 annonces de châteaux ≥ 30 ha (quartiles 1,29-3,07 M€) [A1]
A8: Frais d'acquisition (droits + notaire) | B8: 0.075 | C8: % | D8: EST : DMTO ≈ 5,8-6,3 % + notaire ≈ 1,2 % ; vente SAFER : frais 8,4 % TTC mais exonération de droits possible [A1, PL]
A9: Part du prix affectable au bâti (amortissable) | B9: 0.55 | C9: % | D9: EST
A10: Travaux de restauration / mise aux normes | B10: 500000 | C10: € | D10: EST sans visite : top 5 des biens équipés 0,1-0,7 M€ [A1]
A11: Investissements équestres (boxes, carrière, manège…) | B11: 350000 | C11: € | D11: EST : marcheur 35 k€, carrière 35 €/m², barn 200 €/m² (PL [A3 H19]) + 10 box supplémentaires
A12: Investissements événementiel / hébergement | B12: 80000 | C12: € | D12: EST : salon de réception pour ventes privées, pas de salle ERP > 50 pers.
A13: Répartition travaux : année d'acquisition | B13: 0.6 | C13: % | D13: EST
A14: Répartition travaux : année +1 | B14: 0.3 | C14: % | D14: EST
A15: Répartition travaux : année +2 | B15: 0.1 | C15: % | D15: EST
A16: Gros entretien patrimonial annuel (% prix+travaux) | B16: 0.018 | C16: % | D16: ≈ 41 k€/an sur (bâti + travaux) : Demeure Historique ≥ 40 k€/an hors restauration (PL [A8]) ; Barnes 20-80 k€/an [A4 §11] ; démarre en année d'acquisition + 3
... A20: Loyer de la partie privée payé par le fondateur (hors CA d'exploitation) | B20: 0 | C20: € | D20: Correction audit M1 : aucun loyer privé compté — le logis doit être détenu à part (SCI à l'IR, hors taxe 235 ter C [A6]) et payé par le fondateur personnellement
A22: 2. Financement
A23: Apport du fondateur (année 1) | B23: 1000000 | C23: € | D23: Scénario d'apport S3 (hypothèse ; apport réel inconnu)
A24: Fonds propres apportés à l'acquisition (investisseurs ou holding) | B24: 0 | C24: € | D24: Aucun investisseur
A25: Ces fonds propres viennent-ils de la holding du fondateur ? (1/0) | B25: 0
A26: Subventions (non acquises : 0 par défaut) | B26: 0 | C26: € | D26: Aucune subvention considérée comme acquise
A27: Dette bancaire (année d'acquisition) | B27: 2400000 | C27: € | D27: NON ACQUIS — montage 1 [A2] : prêt hypothécaire 20 ans ; LTV ≈ 70 %, jugée trop élevée par l'agent 2
A28: Taux de la dette bancaire | B28: 0.04 | C28: % | D28: PL : nouveaux crédits PME 3,64 % (FBF, 06/2026) ; EX : 3,66 % (BdF, 08/2026) ; retenu 4,0 % [A2]
A29: Durée dette bancaire | B29: 20 | C29: ans | D29: A2 (Bpifrance : 15 ans avec hypothèque, PL)
A30: Différé d'amortissement (dans la durée) | B30: 1 | C30: ans | D30: EST
A31: Crédit-vendeur | B31: 0 | C31: €
A32: Taux crédit-vendeur | B32: 0.03 | C32: % | D32: EST
A33: Durée crédit-vendeur (amortissable) | B33: 12 | C33: ans | D33: EST
A34: Obligations / quasi-fonds propres (in fine) | B34: 0 | C34: €
A35: Coupon annuel des obligations | B35: 0.07 | C35: % | D35: PL : obligations Château Fontenay 7 % [A2]
A36: Année de remboursement des obligations | B36: 6 | C36: année | D36: EST
A37: Part de capital supplémentaire accordée au fondateur pour son travail (sweat equity) | B37: 0 | C37: % | D37: Fondateur seul
A38: Droits de vote du fondateur | B38: 1 | C38: %
A39: Réserve de liquidité cible | B39: 150000 | C39: € | D39: EST
A40: TRI minimal exigé par des investisseurs extérieurs | B40: 0.06 | C40: % | D40: EST : rendement minimal d'un investisseur en fonds propres illiquide (Anaxago affiche 8,7 % net, PL [A2])
A41: Le dirigeant est-il rémunéré par le domaine ? (1/0) | B41: 1 | D41: Rémunération du dirigeant incluse
A42: Part du capital du fondateur (calculée : apports au prorata + prime d'industrie, plafonnée à 100 %) | B42: =MIN(1,($B$23+$B$24*$B$25)/MAX(1,$B$23+$B$24)+$B$37)
A44: 3. Paramètres de stress (neutres = 100 % / 0)
A45: Multiplicateur de chiffre d'affaires | B45: 1 | C45: % | D45: neutre
A46: Multiplicateur du budget travaux | B46: 1 | C46: % | D46: neutre
...

Sheet B_central
A1: Scénario B — Château multiactivité — cas central
A2: Cellules jaunes/bleues = hypothèses éditables. Tout le reste est calculé. Colonne D (bloc hypothèses) = source ou statut (ESTIMATION = non vérifiée).
A4: 1. Calendrier, acquisition et travaux
A5: Année d'acquisition des murs (1 = immédiate) | B5: 1 | C5: année | D5: Achat immédiat (2027)
A6: Année d'ouverture commerciale (avant stress) | B6: 2 | C6: année | D6: Année 1 = travaux ; EST
A7: Prix d'acquisition | B7: 2500000 | C7: € | D7: PL : médiane de 19 annonces de châteaux ≥ 30 ha (quartiles 1,29-3,07 M€) [A1]
A8: Frais d'acquisition (droits + notaire) | B8: 0.075 | C8: % | D8: EST : DMTO ≈ 5,8-6,3 % + notaire ≈ 1,2 % ; vente SAFER : frais 8,4 % TTC mais exonération de droits possible [A1, PL]
A9: Part du prix affectable au bâti (amortissable) | B9: 0.55 | C9: % | D9: EST
A10: Travaux de restauration / mise aux normes | B10: 500000 | C10: € | D10: EST sans visite : top 5 des biens équipés 0,1-0,7 M€ [A1]
A11: Investissements équestres (boxes, carrière, manège…) | B11: 150000 | C11: € | D11: EST : remise à niveau d'écuries existantes (une écurie neuve de 30 box coûterait 0,78-0,83 M€ HT [A3 H20])
A12: Investissements événementiel / hébergement | B12: 250000 | C12: € | D12: EST : mise aux normes d'une salle existante + aménagement du gîte (neuf : 570 k€-1,24 M€ [A4 §13.2])
A13: Répartition travaux : année d'acquisition | B13: 0.6 | C13: % | D13: EST
A14: Répartition travaux : année +1 | B14: 0.3 | C14: % | D14: EST
A15: Répartition travaux : année +2 | B15: 0.1 | C15: % | D15: EST
A16: Gros entretien patrimonial annuel (% prix+travaux) | B16: 0.018 | C16: % | D16: ≈ 41 k€/an sur (bâti + travaux) : Demeure Historique ≥ 40 k€/an hors restauration (PL [A8]) ; Barnes 20-80 k€/an [A4 §11] ; démarre en année d'acquisition + 3
... A20: Loyer de la partie privée payé par le fondateur (hors CA d'exploitation) | B20: 0 | C20: € | D20: Correction audit M1 : aucun loyer privé compté — le logis doit être détenu à part (SCI à l'IR, hors taxe 235 ter C [A6]) et payé par le fondateur personnellement
A22: 2. Financement
A23: Apport du fondateur (année 1) | B23: 1000000 | C23: € | D23: Scénario d'apport S3 (hypothèse ; apport réel inconnu)
A24: Fonds propres apportés à l'acquisition (investisseurs ou holding) | B24: 0 | C24: € | D24: Aucun investisseur
A25: Ces fonds propres viennent-ils de la holding du fondateur ? (1/0) | B25: 0
A26: Subventions (non acquises : 0 par défaut) | B26: 0 | C26: € | D26: Aucune subvention considérée comme acquise
A27: Dette bancaire (année d'acquisition) | B27: 2400000 | C27: € | D27: NON ACQUIS — montage 1 [A2] : prêt hypothécaire 20 ans ; LTV ≈ 70 %, jugée trop élevée par l'agent 2
A28: Taux de la dette bancaire | B28: 0.04 | C28: % | D28: PL : nouveaux crédits PME 3,64 % (FBF, 06/2026) ; EX : 3,66 % (BdF, 08/2026) ; retenu 4,0 % [A2]
A29: Durée dette bancaire | B29: 20 | C29: ans | D29: A2 (Bpifrance : 15 ans avec hypothèque, PL)
A30: Différé d'amortissement (dans la durée) | B30: 1 | C30: ans | D30: EST
A31: Crédit-vendeur | B31: 0 | C31: €
A32: Taux crédit-vendeur | B32: 0.03 | C32: % | D32: EST
A33: Durée crédit-vendeur (amortissable) | B33: 12 | C33: ans | D33: EST
A34: Obligations / quasi-fonds propres (in fine) | B34: 0 | C34: €
A35: Coupon annuel des obligations | B35: 0.07 | C35: % | D35: PL : obligations Château Fontenay 7 % [A2]
A36: Année de remboursement des obligations | B36: 6 | C36: année | D36: EST
A37: Part de capital supplémentaire accordée au fondateur pour son travail (sweat equity) | B37: 0 | C37: % | D37: Fondateur seul
A38: Droits de vote du fondateur | B38: 1 | C38: %
A39: Réserve de liquidité cible | B39: 150000 | C39: € | D39: EST
A40: TRI minimal exigé par des investisseurs extérieurs | B40: 0.06 | C40: % | D40: EST : rendement minimal d'un investisseur en fonds propres illiquide (Anaxago affiche 8,7 % net, PL [A2])
A41: Le dirigeant est-il rémunéré par le domaine ? (1/0) | B41: 1 | D41: Rémunération du dirigeant incluse
A42: Part du capital du fondateur (calculée : apports au prorata + prime d'industrie, plafonnée à 100 %) | B42: =MIN(1,($B$23+$B$24*$B$25)/MAX(1,$B$23+$B$24)+$B$37)
A44: 3. Paramètres de stress (neutres = 100 % / 0)
A45: Multiplicateur de chiffre d'affaires | B45: 1 | C45: % | D45: neutre
A46: Multiplicateur du budget travaux | B46: 1 | C46: % | D46: neutre
...

Sheet B_prudent
A1: Scénario B — Château multiactivité — cas prudent
A2: Cellules jaunes/bleues = hypothèses éditables. Tout le reste est calculé. Colonne D (bloc hypothèses) = source ou statut (ESTIMATION = non vérifiée).
A4: 1. Calendrier, acquisition et travaux
A5: Année d'acquisition des murs (1 = immédiate) | B5: 1 | C5: année | D5: Achat immédiat (2027)
A6: Année d'ouverture commerciale (avant stress) | B6: 2 | C6: année | D6: Année 1 = travaux ; EST
A7: Prix d'acquisition | B7: 2500000 | C7: € | D7: PL : médiane de 19 annonces de châteaux ≥ 30 ha (quartiles 1,29-3,07 M€) [A1]
A8: Frais d'acquisition (droits + notaire) | B8: 0.075 | C8: % | D8: EST : DMTO ≈ 5,8-6,3 % + notaire ≈ 1,2 % ; vente SAFER : frais 8,4 % TTC mais exonération de droits possible [A1, PL]
A9: Part du prix affectable au bâti (amortissable) | B9: 0.55 | C9: % | D9: EST
A10: Travaux de restauration / mise aux normes | B10: 625000 | C10: € | D10: EST sans visite : top 5 des biens équipés 0,1-0,7 M€ [A1]
A11: Investissements équestres (boxes, carrière, manège…) | B11: 187500 | C11: € | D11: EST : remise à niveau d'écuries existantes (une écurie neuve de 30 box coûterait 0,78-0,83 M€ HT [A3 H20])
A12: Investissements événementiel / hébergement | B12: 312500 | C12: € | D12: EST : mise aux normes d'une salle existante + aménagement du gîte (neuf : 570 k€-1,24 M€ [A4 §13.2])
A13: Répartition travaux : année d'acquisition | B13: 0.6 | C13: % | D13: EST
A14: Répartition travaux : année +1 | B14: 0.3 | C14: % | D14: EST
A15: Répartition travaux : année +2 | B15: 0.1 | C15: % | D15: EST
A16: Gros entretien patrimonial annuel (% prix+travaux) | B16: 0.018 | C16: % | D16: ≈ 41 k€/an sur (bâti + travaux) : Demeure Historique ≥ 40 k€/an hors restauration (PL [A8]) ; Barnes 20-80 k€/an [A4 §11] ; démarre en année d'acquisition + 3
... A20: Loyer de la partie privée payé par le fondateur (hors CA d'exploitation) | B20: 0 | C20: € | D20: Correction audit M1 : aucun loyer privé compté — le logis doit être détenu à part (SCI à l'IR, hors taxe 235 ter C [A6]) et payé par le fondateur personnellement
A22: 2. Financement
A23: Apport du fondateur (année 1) | B23: 1000000 | C23: € | D23: Scénario d'apport S3 (hypothèse ; apport réel inconnu)
A24: Fonds propres apportés à l'acquisition (investisseurs ou holding) | B24: 0 | C24: € | D24: Aucun investisseur
A25: Ces fonds propres viennent-ils de la holding du fondateur ? (1/0) | B25: 0
A26: Subventions (non acquises : 0 par défaut) | B26: 0 | C26: € | D26: Aucune subvention considérée comme acquise
A27: Dette bancaire (année d'acquisition) | B27: 2400000 | C27: € | D27: NON ACQUIS — montage 1 [A2] : prêt hypothécaire 20 ans ; LTV ≈ 70 %, jugée trop élevée par l'agent 2
A28: Taux de la dette bancaire | B28: 0.04 | C28: % | D28: PL : nouveaux crédits PME 3,64 % (FBF, 06/2026) ; EX : 3,66 % (BdF, 08/2026) ; retenu 4,0 % [A2]
A29: Durée dette bancaire | B29: 20 | C29: ans | D29: A2 (Bpifrance : 15 ans avec hypothèque, PL)
A30: Différé d'amortissement (dans la durée) | B30: 1 | C30: ans | D30: EST
A31: Crédit-vendeur | B31: 0 | C31: €
A32: Taux crédit-vendeur | B32: 0.03 | C32: % | D32: EST
A33: Durée crédit-vendeur (amortissable) | B33: 12 | C33: ans | D33: EST
A34: Obligations / quasi-fonds propres (in fine) | B34: 0 | C34: €
A35: Coupon annuel des obligations | B35: 0.07 | C35: % | D35: PL : obligations Château Fontenay 7 % [A2]
A36: Année de remboursement des obligations | B36: 6 | C36: année | D36: EST
A37: Part de capital supplémentaire accordée au fondateur pour son travail (sweat equity) | B37: 0 | C37: % | D37: Fondateur seul
A38: Droits de vote du fondateur | B38: 1 | C38: %
A39: Réserve de liquidité cible | B39: 150000 | C39: € | D39: EST
A40: TRI minimal exigé par des investisseurs extérieurs | B40: 0.06 | C40: % | D40: EST : rendement minimal d'un investisseur en fonds propres illiquide (Anaxago affiche 8,7 % net, PL [A2])
A41: Le dirigeant est-il rémunéré par le domaine ? (1/0) | B41: 1 | D41: Rémunération du dirigeant incluse
A42: Part du capital du fondateur (calculée : apports au prorata + prime d'industrie, plafonnée à 100 %) | B42: =MIN(1,($B$23+$B$24*$B$25)/MAX(1,$B$23+$B$24)+$B$37)
A44: 3. Paramètres de stress (neutres = 100 % / 0)
A45: Multiplicateur de chiffre d'affaires | B45: 1 | C45: % | D45: neutre
A46: Multiplicateur du budget travaux | B46: 1 | C46: % | D46: neutre
...

Sheet B_optimiste
A1: Scénario B — Château multiactivité — cas optimiste
A2: Cellules jaunes/bleues = hypothèses éditables. Tout le reste est calculé. Colonne D (bloc hypothèses) = source ou statut (ESTIMATION = non vérifiée).
A4: 1. Calendrier, acquisition et travaux
A5: Année d'acquisition des murs (1 = immédiate) | B5: 1 | C5: année | D5: Achat immédiat (2027)
A6: Année d'ouverture commerciale (avant stress) | B6: 2 | C6: année | D6: Année 1 = travaux ; EST
A7: Prix d'acquisition | B7: 2500000 | C7: € | D7: PL : médiane de 19 annonces de châteaux ≥ 30 ha (quartiles 1,29-3,07 M€) [A1]
A8: Frais d'acquisition (droits + notaire) | B8: 0.075 | C8: % | D8: EST : DMTO ≈ 5,8-6,3 % + notaire ≈ 1,2 % ; vente SAFER : frais 8,4 % TTC mais exonération de droits possible [A1, PL]
A9: Part du prix affectable au bâti (amortissable) | B9: 0.55 | C9: % | D9: EST
A10: Travaux de restauration / mise aux normes | B10: 500000 | C10: € | D10: EST sans visite : top 5 des biens équipés 0,1-0,7 M€ [A1]
A11: Investissements équestres (boxes, carrière, manège…) | B11: 150000 | C11: € | D11: EST : remise à niveau d'écuries existantes (une écurie neuve de 30 box coûterait 0,78-0,83 M€ HT [A3 H20])
A12: Investissements événementiel / hébergement | B12: 250000 | C12: € | D12: EST : mise aux normes d'une salle existante + aménagement du gîte (neuf : 570 k€-1,24 M€ [A4 §13.2])
A13: Répartition travaux : année d'acquisition | B13: 0.6 | C13: % | D13: EST
A14: Répartition travaux : année +1 | B14: 0.3 | C14: % | D14: EST
A15: Répartition travaux : année +2 | B15: 0.1 | C15: % | D15: EST
A16: Gros entretien patrimonial annuel (% prix+travaux) | B16: 0.018 | C16: % | D16: ≈ 41 k€/an sur (bâti + travaux) : Demeure Historique ≥ 40 k€/an hors restauration (PL [A8]) ; Barnes 20-80 k€/an [A4 §11] ; démarre en année d'acquisition + 3
... A20: Loyer de la partie privée payé par le fondateur (hors CA d'exploitation) | B20: 0 | C20: € | D20: Correction audit M1 : aucun loyer privé compté — le logis doit être détenu à part (SCI à l'IR, hors taxe 235 ter C [A6]) et payé par le fondateur personnellement
A22: 2. Financement
A23: Apport du fondateur (année 1) | B23: 1000000 | C23: € | D23: Scénario d'apport S3 (hypothèse ; apport réel inconnu)
A24: Fonds propres apportés à l'acquisition (investisseurs ou holding) | B24: 0 | C24: € | D24: Aucun investisseur
A25: Ces fonds propres viennent-ils de la holding du fondateur ? (1/0) | B25: 0
A26: Subventions (non acquises : 0 par défaut) | B26: 0 | C26: € | D26: Aucune subvention considérée comme acquise
A27: Dette bancaire (année d'acquisition) | B27: 2400000 | C27: € | D27: NON ACQUIS — montage 1 [A2] : prêt hypothécaire 20 ans ; LTV ≈ 70 %, jugée trop élevée par l'agent 2
A28: Taux de la dette bancaire | B28: 0.04 | C28: % | D28: PL : nouveaux crédits PME 3,64 % (FBF, 06/2026) ; EX : 3,66 % (BdF, 08/2026) ; retenu 4,0 % [A2]
A29: Durée dette bancaire | B29: 20 | C29: ans | D29: A2 (Bpifrance : 15 ans avec hypothèque, PL)
A30: Différé d'amortissement (dans la durée) | B30: 1 | C30: ans | D30: EST
A31: Crédit-vendeur | B31: 0 | C31: €
A32: Taux crédit-vendeur | B32: 0.03 | C32: % | D32: EST
A33: Durée crédit-vendeur (amortissable) | B33: 12 | C33: ans | D33: EST
A34: Obligations / quasi-fonds propres (in fine) | B34: 0 | C34: €
A35: Coupon annuel des obligations | B35: 0.07 | C35: % | D35: PL : obligations Château Fontenay 7 % [A2]
A36: Année de remboursement des obligations | B36: 6 | C36: année | D36: EST
A37: Part de capital supplémentaire accordée au fondateur pour son travail (sweat equity) | B37: 0 | C37: % | D37: Fondateur seul
A38: Droits de vote du fondateur | B38: 1 | C38: %
A39: Réserve de liquidité cible | B39: 150000 | C39: € | D39: EST
A40: TRI minimal exigé par des investisseurs extérieurs | B40: 0.06 | C40: % | D40: EST : rendement minimal d'un investisseur en fonds propres illiquide (Anaxago affiche 8,7 % net, PL [A2])
A41: Le dirigeant est-il rémunéré par le domaine ? (1/0) | B41: 1 | D41: Rémunération du dirigeant incluse
A42: Part du capital du fondateur (calculée : apports au prorata + prime d'industrie, plafonnée à 100 %) | B42: =MIN(1,($B$23+$B$24*$B$25)/MAX(1,$B$23+$B$24)+$B$37)
A44: 3. Paramètres de stress (neutres = 100 % / 0)
A45: Multiplicateur de chiffre d'affaires | B45: 1 | C45: % | D45: neutre
A46: Multiplicateur du budget travaux | B46: 1 | C46: % | D46: neutre
...

Sheet B_club_deal
A1: B — Club deal : apport 250 k€, investisseurs majoritaires (montage 2) — cas central
A2: Cellules jaunes/bleues = hypothèses éditables. Tout le reste est calculé. Colonne D (bloc hypothèses) = source ou statut (ESTIMATION = non vérifiée).
A4: 1. Calendrier, acquisition et travaux
A5: Année d'acquisition des murs (1 = immédiate) | B5: 1 | C5: année | D5: Achat immédiat (2027)
A6: Année d'ouverture commerciale (avant stress) | B6: 2 | C6: année | D6: Année 1 = travaux ; EST
A7: Prix d'acquisition | B7: 2500000 | C7: € | D7: PL : médiane de 19 annonces de châteaux ≥ 30 ha (quartiles 1,29-3,07 M€) [A1]
A8: Frais d'acquisition (droits + notaire) | B8: 0.075 | C8: % | D8: EST : DMTO ≈ 5,8-6,3 % + notaire ≈ 1,2 % ; vente SAFER : frais 8,4 % TTC mais exonération de droits possible [A1, PL]
A9: Part du prix affectable au bâti (amortissable) | B9: 0.55 | C9: % | D9: EST
A10: Travaux de restauration / mise aux normes | B10: 500000 | C10: € | D10: EST sans visite : top 5 des biens équipés 0,1-0,7 M€ [A1]
A11: Investissements équestres (boxes, carrière, manège…) | B11: 150000 | C11: € | D11: EST : remise à niveau d'écuries existantes (une écurie neuve de 30 box coûterait 0,78-0,83 M€ HT [A3 H20])
A12: Investissements événementiel / hébergement | B12: 250000 | C12: € | D12: EST : mise aux normes d'une salle existante + aménagement du gîte (neuf : 570 k€-1,24 M€ [A4 §13.2])
A13: Répartition travaux : année d'acquisition | B13: 0.6 | C13: % | D13: EST
A14: Répartition travaux : année +1 | B14: 0.3 | C14: % | D14: EST
A15: Répartition travaux : année +2 | B15: 0.1 | C15: % | D15: EST
A16: Gros entretien patrimonial annuel (% prix+travaux) | B16: 0.018 | C16: % | D16: ≈ 41 k€/an sur (bâti + travaux) : Demeure Historique ≥ 40 k€/an hors restauration (PL [A8]) ; Barnes 20-80 k€/an [A4 §11] ; démarre en année d'acquisition + 3
... A20: Loyer de la partie privée payé par le fondateur (hors CA d'exploitation) | B20: 0 | C20: € | D20: Correction audit M1 : aucun loyer privé compté — le logis doit être détenu à part (SCI à l'IR, hors taxe 235 ter C [A6]) et payé par le fondateur personnellement
A22: 2. Financement
A23: Apport du fondateur (année 1) | B23: 250000 | C23: € | D23: Scénario d'apport S2
A24: Fonds propres apportés à l'acquisition (investisseurs ou holding) | B24: 1640000 | C24: € | D24: NON ACQUIS — investisseurs à trouver [A2 montage 2]
A25: Ces fonds propres viennent-ils de la holding du fondateur ? (1/0) | B25: 0
A26: Subventions (non acquises : 0 par défaut) | B26: 0 | C26: € | D26: Aucune subvention considérée comme acquise
A27: Dette bancaire (année d'acquisition) | B27: 1800000 | C27: € | D27: NON ACQUIS — LTV ≈ 50 % [A2 montage 2]
A28: Taux de la dette bancaire | B28: 0.04 | C28: % | D28: PL : nouveaux crédits PME 3,64 % (FBF, 06/2026) ; EX : 3,66 % (BdF, 08/2026) ; retenu 4,0 % [A2]
A29: Durée dette bancaire | B29: 20 | C29: ans | D29: A2 (Bpifrance : 15 ans avec hypothèque, PL)
A30: Différé d'amortissement (dans la durée) | B30: 1 | C30: ans | D30: EST
A31: Crédit-vendeur | B31: 0 | C31: €
A32: Taux crédit-vendeur | B32: 0.03 | C32: % | D32: EST
A33: Durée crédit-vendeur (amortissable) | B33: 12 | C33: ans | D33: EST
A34: Obligations / quasi-fonds propres (in fine) | B34: 0 | C34: €
A35: Coupon annuel des obligations | B35: 0.07 | C35: % | D35: PL : obligations Château Fontenay 7 % [A2]
A36: Année de remboursement des obligations | B36: 6 | C36: année | D36: EST
A37: Part de capital supplémentaire accordée au fondateur pour son travail (sweat equity) | B37: 0.05 | C37: % | D37: EST : promote négociée
A38: Droits de vote du fondateur | B38: 0.1 | C38: % | D38: Investisseurs majoritaires [A2]
A39: Réserve de liquidité cible | B39: 150000 | C39: € | D39: EST
A40: TRI minimal exigé par des investisseurs extérieurs | B40: 0.06 | C40: % | D40: EST : rendement minimal d'un investisseur en fonds propres illiquide (Anaxago affiche 8,7 % net, PL [A2])
A41: Le dirigeant est-il rémunéré par le domaine ? (1/0) | B41: 1 | D41: Rémunération du dirigeant incluse
A42: Part du capital du fondateur (calculée : apports au prorata + prime d'industrie, plafonnée à 100 %) | B42: =MIN(1,($B$23+$B$24*$B$25)/MAX(1,$B$23+$B$24)+$B$37)
A44: 3. Paramètres de stress (neutres = 100 % / 0)
A45: Multiplicateur de chiffre d'affaires | B45: 1 | C45: % | D45: neutre
A46: Multiplicateur du budget travaux | B46: 1 | C46: % | D46: neutre
...

Sheet B_credit_vendeur
A1: B — Crédit-vendeur : apport 250 k€, crédit-vendeur 1,0 M€ sur 5 ans aux conditions de marché (montage 3) — cas central
A2: Cellules jaunes/bleues = hypothèses éditables. Tout le reste est calculé. Colonne D (bloc hypothèses) = source ou statut (ESTIMATION = non vérifiée).
A4: 1. Calendrier, acquisition et travaux
A5: Année d'acquisition des murs (1 = immédiate) | B5: 1 | C5: année | D5: Achat immédiat (2027)
A6: Année d'ouverture commerciale (avant stress) | B6: 2 | C6: année | D6: Année 1 = travaux ; EST
A7: Prix d'acquisition | B7: 2500000 | C7: € | D7: PL : médiane de 19 annonces de châteaux ≥ 30 ha (quartiles 1,29-3,07 M€) [A1]
A8: Frais d'acquisition (droits + notaire) | B8: 0.075 | C8: % | D8: EST : DMTO ≈ 5,8-6,3 % + notaire ≈ 1,2 % ; vente SAFER : frais 8,4 % TTC mais exonération de droits possible [A1, PL]
A9: Part du prix affectable au bâti (amortissable) | B9: 0.55 | C9: % | D9: EST
A10: Travaux de restauration / mise aux normes | B10: 500000 | C10: € | D10: EST sans visite : top 5 des biens équipés 0,1-0,7 M€ [A1]
A11: Investissements équestres (boxes, carrière, manège…) | B11: 150000 | C11: € | D11: EST : remise à niveau d'écuries existantes (une écurie neuve de 30 box coûterait 0,78-0,83 M€ HT [A3 H20])
A12: Investissements événementiel / hébergement | B12: 250000 | C12: € | D12: EST : mise aux normes d'une salle existante + aménagement du gîte (neuf : 570 k€-1,24 M€ [A4 §13.2])
A13: Répartition travaux : année d'acquisition | B13: 0.6 | C13: % | D13: EST
A14: Répartition travaux : année +1 | B14: 0.3 | C14: % | D14: EST
A15: Répartition travaux : année +2 | B15: 0.1 | C15: % | D15: EST
A16: Gros entretien patrimonial annuel (% prix+travaux) | B16: 0.018 | C16: % | D16: ≈ 41 k€/an sur (bâti + travaux) : Demeure Historique ≥ 40 k€/an hors restauration (PL [A8]) ; Barnes 20-80 k€/an [A4 §11] ; démarre en année d'acquisition + 3
... A20: Loyer de la partie privée payé par le fondateur (hors CA d'exploitation) | B20: 0 | C20: € | D20: Correction audit M1 : aucun loyer privé compté — le logis doit être détenu à part (SCI à l'IR, hors taxe 235 ter C [A6]) et payé par le fondateur personnellement
A22: 2. Financement
A23: Apport du fondateur (année 1) | B23: 250000 | C23: € | D23: S2 (les prêts d'honneur sont comptés en dette — correction audit)
A24: Fonds propres apportés à l'acquisition (investisseurs ou holding) | B24: 0 | C24: € | D24: Aucun investisseur
A25: Ces fonds propres viennent-ils de la holding du fondateur ? (1/0) | B25: 0
A26: Subventions (non acquises : 0 par défaut) | B26: 0 | C26: € | D26: Aucune subvention considérée comme acquise
A27: Dette bancaire (année d'acquisition) | B27: 1680000 | C27: € | D27: NON ACQUIS — banque 15 ans + prêt OpCo garanti + prêts d'honneur 80 k€ regroupés [A2]
A28: Taux de la dette bancaire | B28: 0.04 | C28: % | D28: PL : nouveaux crédits PME 3,64 % (FBF, 06/2026) ; EX : 3,66 % (BdF, 08/2026) ; retenu 4,0 % [A2]
A29: Durée dette bancaire | B29: 15 | C29: ans | D29: A2
A30: Différé d'amortissement (dans la durée) | B30: 1 | C30: ans | D30: EST
A31: Crédit-vendeur | B31: 1000000 | C31: € | D31: NON ACQUIS — 40 % du prix : usage 30-50 %, 1-5 ans, taux ≥ banque (PL [A8]) ; clause résolutoire
A32: Taux crédit-vendeur | B32: 0.045 | C32: % | D32: PL [A8] : taux ≥ banque
A33: Durée crédit-vendeur (amortissable) | B33: 5 | C33: ans | D33: PL [A8]
A34: Obligations / quasi-fonds propres (in fine) | B34: 500000 | C34: € | D34: NON ACQUIS — obligations PSFP in fine 5 ans [A2]
A35: Coupon annuel des obligations | B35: 0.08 | C35: % | D35: A2 : 7-9 %
A36: Année de remboursement des obligations | B36: 6 | C36: année | D36: Remboursement in fine en année 6
A37: Part de capital supplémentaire accordée au fondateur pour son travail (sweat equity) | B37: 0 | C37: % | D37: Fondateur seul
A38: Droits de vote du fondateur | B38: 1 | C38: %
A39: Réserve de liquidité cible | B39: 150000 | C39: € | D39: EST
A40: TRI minimal exigé par des investisseurs extérieurs | B40: 0.06 | C40: % | D40: EST : rendement minimal d'un investisseur en fonds propres illiquide (Anaxago affiche 8,7 % net, PL [A2])
A41: Le dirigeant est-il rémunéré par le domaine ? (1/0) | B41: 1 | D41: Rémunération du dirigeant incluse
A42: Part du capital du fondateur (calculée : apports au prorata + prime d'industrie, plafonnée à 100 %) | B42: =MIN(1,($B$23+$B$24*$B$25)/MAX(1,$B$23+$B$24)+$B$37)
A44: 3. Paramètres de stress (neutres = 100 % / 0)
A45: Multiplicateur de chiffre d'affaires | B45: 1 | C45: % | D45: neutre
A46: Multiplicateur du budget travaux | B46: 1 | C46: % | D46: neutre
...

Sheet B_sans_dette
A1: Diagnostic — exploitation B sans aucune dette (tout en fonds propres)
A2: Cellules jaunes/bleues = hypothèses éditables. Tout le reste est calculé. Colonne D (bloc hypothèses) = source ou statut (ESTIMATION = non vérifiée).
A4: 1. Calendrier, acquisition et travaux
A5: Année d'acquisition des murs (1 = immédiate) | B5: 1 | C5: année | D5: Achat immédiat (2027)
A6: Année d'ouverture commerciale (avant stress) | B6: 2 | C6: année | D6: Année 1 = travaux ; EST
A7: Prix d'acquisition | B7: 2500000 | C7: € | D7: PL : médiane de 19 annonces de châteaux ≥ 30 ha (quartiles 1,29-3,07 M€) [A1]
